Workbook

Sheet Updated allotments
A1: Classwise subjects allotment for 2025-26
B2: 6A | C2: 6B | D2: 7A | E2: 7B | F2: 8A | G2: 8B | H2: 9A | I2: 9B | J2: 9C | K2: 10A | L2: 10B | M2: 10C | N2: 11A | O2: 11B | P2: 12A | Q2: 12B
A3: I/C | B3: RS | C3: GK | D3: RN | E3: RJ | F3: SH | G3: RI | H3: PR | I3: MK | J3: VS | K3: MB | L3: SU | M3: AB | N3: MR | O3: SN | P3: AS | Q3: SK
A4: ENG | B4: PR | C4: JL | D4: RJ | E4: RJ | F4: SN | G4: SN | H4: PR | I4: RJ | J4: MB | K4: MB | L4: PR | M4: MB | N4: AA | O4: AA | P4: AA | Q4: AA
A5: PBI | B5: AB | C5: GK | D5: GK | E5: AB | F5: AB | G5: GK | H5: AB | I5: GK | J5: GK | K5: GK | L5: AB | M5: AB | N5: AS | O5: AS | P5: AS | Q5: AS
A6: HIN | B6: RL | C6: MA | D6: MA | E6: SR | F6: MA | G6: RL | H6: MA | I6: RL | J6: RL | K6: RL | L6: MA | M6: MA | N6: -- | O6: -- | P6: -- | Q6: --
A7: SCI | B7: VS | C7: SU | D7: RI | E7: SU | F7: VS | G7: RI | H7: SU | I7: RI | J7: VS | K7: RI | L7: SU | M7: VS | N7: -- | O7: -- | P7: -- | Q7: --
A8: MATH | B8: RS | C8: SH | D8: RN | E8: MK | F8: SH | G8: RN | H8: RN | I8: MK | J8: RS | K8: MK | L8: RS | M8: SH | N8: SK | O8: SK | P8: SK | Q8: SK
A9: SS | B9: RJ | C9: PR | D9: JL | E9: PR | F9: RJ | G9: JL | H9: JL | I9: SN | J9: RJ | K9: JL | L9: MB | M9: MB | N9: -- | O9: -- | P9: -- | Q9: --
A10: CS | B10: SJ | C10: JK | D10: JK | E10: SJ | F10: SJ | G10: JK | H10: JK | I10: SJ | J10: JK | K10: SJ | L10: SJ | M10: JK | N10: JK | O10: SJ | P10: SJ | Q10: JK
A11: PE | B11: DR | C11: RN | D11: SH | E11: DR | F11: RK | G11: DR | H11: DR | I11: RK | J11: RK | K11: RK | L11: DR | M11: DR | N11: DR | O11: RK | P11: RK | Q11: DR
A12: HIS | B12: -- | C12: -- | D12: -- | E12: -- | F12: -- | G12: -- | H12: -- | I12: -- | J12: -- | K12: -- | L12: -- | M12: -- | N12: RL | O12: SK | P12: SN | Q12: SN
A13: POL | B13: -- | C13: -- | D13: -- | E13: -- | F13: -- | G13: -- | H13: -- | I13: -- | J13: -- | K13: -- | L13: -- | M13: -- | N13: MR | O13: MR | P13: MR | Q13: MR

Sheet Allotments (obsolete)
A1: Sr# | B1: Names | C1: 6A | D1: 6B | E1: 7A | F1: 7B | G1: 8A | H1: 8B | I1: 9A | J1: 9B | K1: 9C | L1: 10A | M1: 10B | N1: 10C | O1: 11A | P1: 11B | Q1: 12A | R1: 12B
B2: INCHARGES | C2: RS | D2: GK | E2: RN | F2: RJ | G2: SH | H2: RI | I2: PR | J2: MK | K2: VS | L2: MB | M2: SU | N2: AB | O2: MR | P2: SN | Q2: AS | R2: SK
A3: 1 | B3: PR
A4: 2 | B4: AA | O4: EN | P4: EN | Q4: EN | R4: EN
A5: 3 | B5: MR | O5: POL | P5: POL | Q5: POL | R5: POL
A6: 4 | B6: SK | O6: MATH | P6: MATH, HIS | Q6: MATH | R6: MATH
A7: 5 | B7: AS | O7: PBI | P7: PBI | Q7: PBI | R7: PBI
A8: 6 | B8: DR | C8: PE | G8: PE | N8: PE | P8: PE | Q8: PE
A9: 7 | B9: RK | F9: PE | K9: PE | M9: PE | O9: PE | R9: PE
A10: 8 | B10: JK | C10: CS | E10: CS | H10: CS | I10: CS | K10: CS | N10: CS | P10: CS | Q10: CS
A11: 9 | B11: SJ | D11: CS | F11: CS | G11: CS | J11: CS | L11: CS | M11: CS | O11: CS | R11: CS
A12: 10 | B12: JP | I12: PLB | L12: PLB | O12: PLB | Q12: PLB
A13: 11 | B13: AR | I13: IT | L13: IT | O13: HIS | P13: IT | Q13: IT
A14: 12 | B14: MK | F14: MATH | J14: MATH | L14: MATH, PE
A15: 13 | B15: SH | E15: PE | G15: MATH | J15: PE | K15: MATH | N15: MATH
A16: 14 | B16: RN | D16: MATH, PE | E16: MATH | H16: MATH
A17: 15 | B17: RS | C17: MATH | H17: PE | I17: MATH, PE | M17: MATH
A18: 16 | B18: AB | C18: PBI | F18: PBI | G18: PBI | I18: PBI | M18: PBI | N18: PBI
A19: 17 | B19: GK | D19: PBI | E19: PBI | H19: PBI | J19: PBI | K19: PBI | L19: PBI
A20: 18 | B20: VS | G20: SCI, AG | J20: SCI, AG | K20: SCI | N20: SCI
A21: 19 | B21: SU | D21: SCI | F21: SCI, AG | I21: SCI, AG | M21: SCI
A22: 20 | B22: RI | C22: SCI | E22: SCI, AG | H22: SCI, AG | L22: SCI
A23: 21 | B23: JL | C23: SS | H23: SS | I23: SS | L23: SS | N23: EN
A24: 22 | B24: MB | D24: EN | K24: EN | L24: EN | M24: SS | N24: SS
A25: 23 | B25: RJ | E25: EN | F25: EN | G25: SS | J25: EN | K25: SS
A26: 24 | B26: SN | G26: EN | H26: EN | J26: SS | Q26: HIS | R26: HIS
A27: 25 | B27: PR | C27: EN | D27: SS | F27: SS | I27: EN | M27: EN
A28: 26 | B28: MA | D28: HI | E28: SS | G28: HI | J28: HI | M28: HI | N28: HI
A29: 27 | B29: RL | C29: HI | E29: HI | F29: HI | H29: HI | I29: HI | K29: HI | L29: HI
A30: 28 | B30: SR

Sheet Periods
A1: Sr# | B1: Names | C1: Class I/C | D1: 6A | E1: 6B | F1: 7A | G1: 7B | H1: 8A | I1: 8B | J1: 9A | K1: 9B | L1: 9C | M1: 10A | N1: 10B | O1: 10C | P1: TOTAL PERIODS | Q1: 11A | R1: 11B | S1: 12A | T1: 12B | U1: 11-12 Periods | V1: Grand Total Periods
A3: 1 | B3: PS | D3: =IFERROR(VLOOKUP(LEFT(D$1, LEN(D$1)-1)&TRIM('Allotments (obsolete)'!C3), numPeriods!$A$2:$B$85, 2, 0), 0) -> 0 | E3: =IFERROR(VLOOKUP(LEFT(E$1, LEN(E$1)-1)&TRIM('Allotments (obsolete)'!D3), numPeriods!$A$2:$B$85, 2, 0), 0) -> 0 | F3: =IFERROR(VLOOKUP(LEFT(F$1, LEN(F$1)-1)&TRIM('Allotments (obsolete)'!E3), numPeriods!$A$2:$B$85, 2, 0), 0) -> 0 | G3: =IFERROR(VLOOKUP(LEFT(G$1, LEN(G$1)-1)&TRIM('Allotments (obsolete)'!F3), numPeriods!$A$2:$B$85, 2, 0), 0) -> 0 | H3: =IFERROR(VLOOKUP(LEFT(H$1, LEN(H$1)-1)&TRIM('Allotments (obsolete)'!G3), numPeriods!$A$2:$B$85, 2, 0), 0) -> 0 | I3: =IFERROR(VLOOKUP(LEFT(I$1, LEN(I$1)-1)&TRIM('Allotments (obsolete)'!H3), numPeriods!$A$2:$B$85, 2, 0), 0) -> 0 | J3: =IFERROR(VLOOKUP(LEFT(J$1, LEN(J$1)-1)&TRIM('Allotments (obsolete)'!I3), numPeriods!$A$2:$B$85, 2, 0), 0) -> 0 | K3: =IFERROR(VLOOKUP(LEFT(K$1, LEN(K$1)-1)&TRIM('Allotments (obsolete)'!J3), numPeriods!$A$2:$B$85, 2, 0), 0) -> 0 | ... O3: =IFERROR(VLOOKUP(LEFT(O$1, LEN(O$1)-1)&TRIM('Allotments (obsolete)'!N3), numPeriods!$A$2:$B$85, 2, 0), 0) -> 0 | P3: =SUM(D3:O3) -> 0 | V3: =P3+U3 -> 0
A4: 2 | B4: AA | D4: =IFERROR(VLOOKUP(LEFT(D$1, LEN(D$1)-1)&TRIM('Allotments (obsolete)'!C4), numPeriods!$A$2:$B$85, 2, 0), 0) -> 0 | E4: =IFERROR(VLOOKUP(LEFT(E$1, LEN(E$1)-1)&TRIM('Allotments (obsolete)'!D4), numPeriods!$A$2:$B$85, 2, 0), 0) -> 0 | F4: =IFERROR(VLOOKUP(LEFT(F$1, LEN(F$1)-1)&TRIM('Allotments (obsolete)'!E4), numPeriods!$A$2:$B$85, 2, 0), 0) -> 0 | G4: =IFERROR(VLOOKUP(LEFT(G$1, LEN(G$1)-1)&TRIM('Allotments (obsolete)'!F4), numPeriods!$A$2:$B$85, 2, 0), 0) -> 0 | H4: =IFERROR(VLOOKUP(LEFT(H$1, LEN(H$1)-1)&TRIM('Allotments (obsolete)'!G4), numPeriods!$A$2:$B$85, 2, 0), 0) -> 0 | I4: =IFERROR(VLOOKUP(LEFT(I$1, LEN(I$1)-1)&TRIM('Allotments (obsolete)'!H4), numPeriods!$A$2:$B$85, 2, 0), 0) -> 0 | J4: =IFERROR(VLOOKUP(LEFT(J$1, LEN(J$1)-1)&TRIM('Allotments (obsolete)'!I4), numPeriods!$A$2:$B$85, 2, 0), 0) -> 0 | K4: =IFERROR(VLOOKUP(LEFT(K$1, LEN(K$1)-1)&TRIM('Allotments (obsolete)'!J4), numPeriods!$A$2:$B$85, 2, 0), 0) -> 0 | ... O4: =IFERROR(VLOOKUP(LEFT(O$1, LEN(O$1)-1)&TRIM('Allotments (obsolete)'!N4), numPeriods!$A$2:$B$85, 2, 0), 0) -> 0 | P4: =SUM(D4:O4) -> 0 | Q4: EN | R4: EN | S4: EN | T4: EN | U4: 36 | V4: =P4+U4 -> 36
A5: 3 | B5: MR | C5: 11B | D5: =IFERROR(VLOOKUP(LEFT(D$1, LEN(D$1)-1)&TRIM('Allotments (obsolete)'!C5), numPeriods!$A$2:$B$85, 2, 0), 0) -> 0 | E5: =IFERROR(VLOOKUP(LEFT(E$1, LEN(E$1)-1)&TRIM('Allotments (obsolete)'!D5), numPeriods!$A$2:$B$85, 2, 0), 0) -> 0 | F5: =IFERROR(VLOOKUP(LEFT(F$1, LEN(F$1)-1)&TRIM('Allotments (obsolete)'!E5), numPeriods!$A$2:$B$85, 2, 0), 0) -> 0 | G5: =IFERROR(VLOOKUP(LEFT(G$1, LEN(G$1)-1)&TRIM('Allotments (obsolete)'!F5), numPeriods!$A$2:$B$85, 2, 0), 0) -> 0 | H5: =IFERROR(VLOOKUP(LEFT(H$1, LEN(H$1)-1)&TRIM('Allotments (obsolete)'!G5), numPeriods!$A$2:$B$85, 2, 0), 0) -> 0 | I5: =IFERROR(VLOOKUP(LEFT(I$1, LEN(I$1)-1)&TRIM('Allotments (obsolete)'!H5), numPeriods!$A$2:$B$85, 2, 0), 0) -> 0 | J5: =IFERROR(VLOOKUP(LEFT(J$1, LEN(J$1)-1)&TRIM('Allotments (obsolete)'!I5), numPeriods!$A$2:$B$85, 2, 0), 0) -> 0 | K5: =IFERROR(VLOOKUP(LEFT(K$1, LEN(K$1)-1)&TRIM('Allotments (obsolete)'!J5), numPeriods!$A$2:$B$85, 2, 0), 0) -> 0 | ... O5: =IFERROR(VLOOKUP(LEFT(O$1, LEN(O$1)-1)&TRIM('Allotments (obsolete)'!N5), numPeriods!$A$2:$B$85, 2, 0), 0) -> 0 | P5: =SUM(D5:O5) -> 0 | Q5: POL | R5: POL | S5: POL | T5: POL | U5: 36 | V5: =P5+U5 -> 36
A6: 4 | B6: SK | C6: 12B | D6: =IFERROR(VLOOKUP(LEFT(D$1, LEN(D$1)-1)&TRIM('Allotments (obsolete)'!C6), numPeriods!$A$2:$B$85, 2, 0), 0) -> 0 | E6: =IFERROR(VLOOKUP(LEFT(E$1, LEN(E$1)-1)&TRIM('Allotments (obsolete)'!D6), numPeriods!$A$2:$B$85, 2, 0), 0) -> 0 | F6: =IFERROR(VLOOKUP(LEFT(F$1, LEN(F$1)-1)&TRIM('Allotments (obsolete)'!E6), numPeriods!$A$2:$B$85, 2, 0), 0) -> 0 | G6: =IFERROR(VLOOKUP(LEFT(G$1, LEN(G$1)-1)&TRIM('Allotments (obsolete)'!F6), numPeriods!$A$2:$B$85, 2, 0), 0) -> 0 | H6: =IFERROR(VLOOKUP(LEFT(H$1, LEN(H$1)-1)&TRIM('Allotments (obsolete)'!G6), numPeriods!$A$2:$B$85, 2, 0), 0) -> 0 | I6: =IFERROR(VLOOKUP(LEFT(I$1, LEN(I$1)-1)&TRIM('Allotments (obsolete)'!H6), numPeriods!$A$2:$B$85, 2, 0), 0) -> 0 | J6: =IFERROR(VLOOKUP(LEFT(J$1, LEN(J$1)-1)&TRIM('Allotments (obsolete)'!I6), numPeriods!$A$2:$B$85, 2, 0), 0) -> 0 | K6: =IFERROR(VLOOKUP(LEFT(K$1, LEN(K$1)-1)&TRIM('Allotments (obsolete)'!J6), numPeriods!$A$2:$B$85, 2, 0), 0) -> 0 | ... O6: =IFERROR(VLOOKUP(LEFT(O$1, LEN(O$1)-1)&TRIM('Allotments (obsolete)'!N6), numPeriods!$A$2:$B$85, 2, 0), 0) -> 0 | P6: =SUM(D6:O6) -> 0 | Q6: MATH | R6: MATH, HIS | S6: MATH | T6: MATH | U6: 27 | V6: =P6+U6 -> 27
A7: 5 | B7: AS | C7: 12A | D7: =IFERROR(VLOOKUP(LEFT(D$1, LEN(D$1)-1)&TRIM('Allotments (obsolete)'!C7), numPeriods!$A$2:$B$85, 2, 0), 0) -> 0 | E7: =IFERROR(VLOOKUP(LEFT(E$1, LEN(E$1)-1)&TRIM('Allotments (obsolete)'!D7), numPeriods!$A$2:$B$85, 2, 0), 0) -> 0 | F7: =IFERROR(VLOOKUP(LEFT(F$1, LEN(F$1)-1)&TRIM('Allotments (obsolete)'!E7), numPeriods!$A$2:$B$85, 2, 0), 0) -> 0 | G7: =IFERROR(VLOOKUP(LEFT(G$1, LEN(G$1)-1)&TRIM('Allotments (obsolete)'!F7), numPeriods!$A$2:$B$85, 2, 0), 0) -> 0 | H7: =IFERROR(VLOOKUP(LEFT(H$1, LEN(H$1)-1)&TRIM('Allotments (obsolete)'!G7), numPeriods!$A$2:$B$85, 2, 0), 0) -> 0 | I7: =IFERROR(VLOOKUP(LEFT(I$1, LEN(I$1)-1)&TRIM('Allotments (obsolete)'!H7), numPeriods!$A$2:$B$85, 2, 0), 0) -> 0 | J7: =IFERROR(VLOOKUP(LEFT(J$1, LEN(J$1)-1)&TRIM('Allotments (obsolete)'!I7), numPeriods!$A$2:$B$85, 2, 0), 0) -> 0 | K7: =IFERROR(VLOOKUP(LEFT(K$1, LEN(K$1)-1)&TRIM('Allotments (obsolete)'!J7), numPeriods!$A$2:$B$85, 2, 0), 0) -> 0 | ... O7: =IFERROR(VLOOKUP(LEFT(O$1, LEN(O$1)-1)&TRIM('Allotments (obsolete)'!N7), numPeriods!$A$2:$B$85, 2, 0), 0) -> 0 | P7: =SUM(D7:O7) -> 0 | Q7: PBI | R7: PBI | S7: PBI | T7: PBI | U7: 28 | V7: =P7+U7 -> 28
A8: 6 | B8: DR | D8: =IFERROR(VLOOKUP(LEFT(D$1, LEN(D$1)-1)&TRIM('Allotments (obsolete)'!C8), numPeriods!$A$2:$B$85, 2, 0), 0) -> 2 | E8: =IFERROR(VLOOKUP(LEFT(E$1, LEN(E$1)-1)&TRIM('Allotments (obsolete)'!C8), numPeriods!$A$2:$B$85, 2, 0), 0) -> 2 | F8: =IFERROR(VLOOKUP(LEFT(F$1, LEN(F$1)-1)&TRIM('Allotments (obsolete)'!E8), numPeriods!$A$2:$B$85, 2, 0), 0) -> 0 | G8: =IFERROR(VLOOKUP(LEFT(G$1, LEN(G$1)-1)&TRIM('Allotments (obsolete)'!F8), numPeriods!$A$2:$B$85, 2, 0), 0) -> 0 | H8: =IFERROR(VLOOKUP(LEFT(H$1, LEN(H$1)-1)&TRIM('Allotments (obsolete)'!G8), numPeriods!$A$2:$B$85, 2, 0), 0) -> 2 | I8: =IFERROR(VLOOKUP(LEFT(I$1, LEN(I$1)-1)&TRIM('Allotments (obsolete)'!H8), numPeriods!$A$2:$B$85, 2, 0), 0) -> 0 | J8: =IFERROR(VLOOKUP(LEFT(J$1, LEN(J$1)-1)&TRIM('Allotments (obsolete)'!I8), numPeriods!$A$2:$B$85, 2, 0), 0) -> 0 | K8: =IFERROR(VLOOKUP(LEFT(K$1, LEN(K$1)-1)&TRIM('Allotments (obsolete)'!J8), numPeriods!$A$2:$B$85, 2, 0), 0) -> 0 | L8: =IFERROR(VLOOKUP(LEFT(L$1, LEN(L$1)-1)&TRIM('Allotments (obsolete)'!K8), numPeriods!$A$2:$B$85, 2, 0), 0) -> 0 | M8: =IFERROR(VLOOKUP(LEFT(M$1, LEN(M$1)-1)&TRIM('Allotments (obsolete)'!L8), numPeriods!$A$2:$B$85, 2, 0), 0) -> 0 | ... O8: =IFERROR(VLOOKUP(LEFT(O$1, LEN(O$1)-1)&TRIM('Allotments (obsolete)'!N8), numPeriods!$A$2:$B$85, 2, 0), 0) -> 6 | P8: =SUM(D8:O8) -> 12 | R8: PE | S8: PE | U8: 18 | V8: =P8+U8 -> 30
A9: 7 | B9: RK | D9: =IFERROR(VLOOKUP(LEFT(D$1, LEN(D$1)-1)&TRIM('Allotments (obsolete)'!C9), numPeriods!$A$2:$B$85, 2, 0), 0) -> 0 | E9: =IFERROR(VLOOKUP(LEFT(E$1, LEN(E$1)-1)&TRIM('Allotments (obsolete)'!D9), numPeriods!$A$2:$B$85, 2, 0), 0) -> 0 | F9: =IFERROR(VLOOKUP(LEFT(F$1, LEN(F$1)-1)&TRIM('Allotments (obsolete)'!E9), numPeriods!$A$2:$B$85, 2, 0), 0) -> 0 | G9: =IFERROR(VLOOKUP(LEFT(G$1, LEN(G$1)-1)&TRIM('Allotments (obsolete)'!F9), numPeriods!$A$2:$B$85, 2, 0), 0) -> 2 | H9: =IFERROR(VLOOKUP(LEFT(H$1, LEN(H$1)-1)&TRIM('Allotments (obsolete)'!G9), numPeriods!$A$2:$B$85, 2, 0), 0) -> 0 | I9: =IFERROR(VLOOKUP(LEFT(I$1, LEN(I$1)-1)&TRIM('Allotments (obsolete)'!H9), numPeriods!$A$2:$B$85, 2, 0), 0) -> 0 | J9: =IFERROR(VLOOKUP(LEFT(J$1, LEN(J$1)-1)&TRIM('Allotments (obsolete)'!I9), numPeriods!$A$2:$B$85, 2, 0), 0) -> 0 | K9: =IFERROR(VLOOKUP(LEFT(K$1, LEN(K$1)-1)&TRIM('Allotments (obsolete)'!J9), numPeriods!$A$2:$B$85, 2, 0), 0) -> 0 | ... O9: =IFERROR(VLOOKUP(LEFT(O$1, LEN(O$1)-1)&TRIM('Allotments (obsolete)'!N9), numPeriods!$A$2:$B$85, 2, 0), 0) -> 0 | P9: =SUM(D9:O9) -> 14 | Q9: PE | T9: PE | U9: 18 | V9: =P9+U9 -> 32
A10: 8 | B10: JK | D10: =IFERROR(VLOOKUP(LEFT(D$1, LEN(D$1)-1)&TRIM('Allotments (obsolete)'!C10), numPeriods!$A$2:$B$85, 2, 0), 0) -> 4 | E10: =IFERROR(VLOOKUP(LEFT(E$1, LEN(E$1)-1)&TRIM('Allotments (obsolete)'!D10), numPeriods!$A$2:$B$85, 2, 0), 0) -> 0 | F10: =IFERROR(VLOOKUP(LEFT(F$1, LEN(F$1)-1)&TRIM('Allotments (obsolete)'!E10), numPeriods!$A$2:$B$85, 2, 0), 0) -> 4 | G10: =IFERROR(VLOOKUP(LEFT(G$1, LEN(G$1)-1)&TRIM('Allotments (obsolete)'!F10), numPeriods!$A$2:$B$85, 2, 0), 0) -> 0 | H10: =IFERROR(VLOOKUP(LEFT(H$1, LEN(H$1)-1)&TRIM('Allotments (obsolete)'!G10), numPeriods!$A$2:$B$85, 2, 0), 0) -> 0 | I10: =IFERROR(VLOOKUP(LEFT(I$1, LEN(I$1)-1)&TRIM('Allotments (obsolete)'!H10), numPeriods!$A$2:$B$85, 2, 0), 0) -> 4 | J10: =IFERROR(VLOOKUP(LEFT(J$1, LEN(J$1)-1)&TRIM('Allotments (obsolete)'!I10), numPeriods!$A$2:$B$85, 2, 0), 0) -> 4 | K10: =IFERROR(VLOOKUP(LEFT(K$1, LEN(K$1)-1)&TRIM('Allotments (obsolete)'!J10), numPeriods!$A$2:$B$85, 2, 0), 0) -> 0 | ... O10: =IFERROR(VLOOKUP(LEFT(O$1, LEN(O$1)-1)&TRIM('Allotments (obsolete)'!N10), numPeriods!$A$2:$B$85, 2, 0), 0) -> 4 | P10: =SUM(D10:O10) -> 24 | R10: CS | S10: CS | U10: 8 | V10: =P10+U10 -> 32
A11: 9 | B11: SJ | D11: =IFERROR(VLOOKUP(LEFT(D$1, LEN(D$1)-1)&TRIM('Allotments (obsolete)'!C11), numPeriods!$A$2:$B$85, 2, 0), 0) -> 0 | E11: =IFERROR(VLOOKUP(LEFT(E$1, LEN(E$1)-1)&TRIM('Allotments (obsolete)'!D11), numPeriods!$A$2:$B$85, 2, 0), 0) -> 4 | F11: =IFERROR(VLOOKUP(LEFT(F$1, LEN(F$1)-1)&TRIM('Allotments (obsolete)'!E11), numPeriods!$A$2:$B$85, 2, 0), 0) -> 0 | G11: =IFERROR(VLOOKUP(LEFT(G$1, LEN(G$1)-1)&TRIM('Allotments (obsolete)'!F11), numPeriods!$A$2:$B$85, 2, 0), 0) -> 4 | H11: =IFERROR(VLOOKUP(LEFT(H$1, LEN(H$1)-1)&TRIM('Allotments (obsolete)'!G11), numPeriods!$A$2:$B$85, 2, 0), 0) -> 4 | I11: =IFERROR(VLOOKUP(LEFT(I$1, LEN(I$1)-1)&TRIM('Allotments (obsolete)'!H11), numPeriods!$A$2:$B$85, 2, 0), 0) -> 0 | J11: =IFERROR(VLOOKUP(LEFT(J$1, LEN(J$1)-1)&TRIM('Allotments (obsolete)'!I11), numPeriods!$A$2:$B$85, 2, 0), 0) -> 0 | K11: =IFERROR(VLOOKUP(LEFT(K$1, LEN(K$1)-1)&TRIM('Allotments (obsolete)'!J11), numPeriods!$A$2:$B$85, 2, 0), 0) -> 4 | ... O11: =IFERROR(VLOOKUP(LEFT(O$1, LEN(O$1)-1)&TRIM('Allotments (obsolete)'!N11), numPeriods!$A$2:$B$85, 2, 0), 0) -> 0 | P11: =SUM(D11:O11) -> 24 | Q11: CS | T11: CS | U11: 8 | V11: =P11+U11 -> 32
A12: 10 | B12: JP | D12: =IFERROR(VLOOKUP(LEFT(D$1, LEN(D$1)-1)&TRIM('Allotments (obsolete)'!C12), numPeriods!$A$2:$B$85, 2, 0), 0) -> 0 | E12: =IFERROR(VLOOKUP(LEFT(E$1, LEN(E$1)-1)&TRIM('Allotments (obsolete)'!D12), numPeriods!$A$2:$B$85, 2, 0), 0) -> 0 | F12: =IFERROR(VLOOKUP(LEFT(F$1, LEN(F$1)-1)&TRIM('Allotments (obsolete)'!E12), numPeriods!$A$2:$B$85, 2, 0), 0) -> 0 | G12: =IFERROR(VLOOKUP(LEFT(G$1, LEN(G$1)-1)&TRIM('Allotments (obsolete)'!F12), numPeriods!$A$2:$B$85, 2, 0), 0) -> 0 | H12: =IFERROR(VLOOKUP(LEFT(H$1, LEN(H$1)-1)&TRIM('Allotments (obsolete)'!G12), numPeriods!$A$2:$B$85, 2, 0), 0) -> 0 | I12: =IFERROR(VLOOKUP(LEFT(I$1, LEN(I$1)-1)&TRIM('Allotments (obsolete)'!H12), numPeriods!$A$2:$B$85, 2, 0), 0) -> 0 | J12: =IFERROR(VLOOKUP(LEFT(J$1, LEN(J$1)-1)&TRIM('Allotments (obsolete)'!I12), numPeriods!$A$2:$B$85, 2, 0), 0) -> 6 | K12: =IFERROR(VLOOKUP(LEFT(K$1, LEN(K$1)-1)&TRIM('Allotments (obsolete)'!J12), numPeriods!$A$2:$B$85, 2, 0), 0) -> 0 | ... O12: =IFERROR(VLOOKUP(LEFT(O$1, LEN(O$1)-1)&TRIM('Allotments (obsolete)'!N12), numPeriods!$A$2:$B$85, 2, 0), 0) -> 0 | P12: =SUM(D12:O12) -> 12 | Q12: PLB | R12: PLB | S12: PLB | T12: PLB | U12: 18 | V12: =P12+U12 -> 30
A13: 11 | B13: AR | D13: =IFERROR(VLOOKUP(LEFT(D$1, LEN(D$1)-1)&TRIM('Allotments (obsolete)'!C13), numPeriods!$A$2:$B$85, 2, 0), 0) -> 0 | E13: =IFERROR(VLOOKUP(LEFT(E$1, LEN(E$1)-1)&TRIM('Allotments (obsolete)'!D13), numPeriods!$A$2:$B$85, 2, 0), 0) -> 0 | F13: =IFERROR(VLOOKUP(LEFT(F$1, LEN(F$1)-1)&TRIM('Allotments (obsolete)'!E13), numPeriods!$A$2:$B$85, 2, 0), 0) -> 0 | G13: =IFERROR(VLOOKUP(LEFT(G$1, LEN(G$1)-1)&TRIM('Allotments (obsolete)'!F13), numPeriods!$A$2:$B$85, 2, 0), 0) -> 0 | H13: =IFERROR(VLOOKUP(LEFT(H$1, LEN(H$1)-1)&TRIM('Allotments (obsolete)'!G13), numPeriods!$A$2:$B$85, 2, 0), 0) -> 0 | I13: =IFERROR(VLOOKUP(LEFT(I$1, LEN(I$1)-1)&TRIM('Allotments (obsolete)'!H13), numPeriods!$A$2:$B$85, 2, 0), 0) -> 0 | J13: =IFERROR(VLOOKUP(LEFT(J$1, LEN(J$1)-1)&TRIM('Allotments (obsolete)'!I13), numPeriods!$A$2:$B$85, 2, 0), 0) -> 6 | K13: =IFERROR(VLOOKUP(LEFT(K$1, LEN(K$1)-1)&TRIM('Allotments (obsolete)'!J13), numPeriods!$A$2:$B$85, 2, 0), 0) -> 0 | ... O13: =IFERROR(VLOOKUP(LEFT(O$1, LEN(O$1)-1)&TRIM('Allotments (obsolete)'!N13), numPeriods!$A$2:$B$85, 2, 0), 0) -> 0 | P13: =SUM(D13:O13) -> 12 | Q13: IT | R13: IT | S13: IT | T13: IT | U13: 27 | V13: 30
A14: 12 | B14: MK | C14: 9B | D14: =IFERROR(VLOOKUP(LEFT(D$1, LEN(D$1)-1)&TRIM('Allotments (obsolete)'!C14), numPeriods!$A$2:$B$85, 2, 0), 0) -> 0 | E14: =IFERROR(VLOOKUP(LEFT(E$1, LEN(E$1)-1)&TRIM('Allotments (obsolete)'!D14), numPeriods!$A$2:$B$85, 2, 0), 0) -> 0 | F14: =IFERROR(VLOOKUP(LEFT(F$1, LEN(F$1)-1)&TRIM('Allotments (obsolete)'!E14), numPeriods!$A$2:$B$85, 2, 0), 0) -> 0 | G14: =IFERROR(VLOOKUP(LEFT(G$1, LEN(G$1)-1)&TRIM('Allotments (obsolete)'!F14), numPeriods!$A$2:$B$85, 2, 0), 0) -> 8 | H14: =IFERROR(VLOOKUP(LEFT(H$1, LEN(H$1)-1)&TRIM('Allotments (obsolete)'!G14), numPeriods!$A$2:$B$85, 2, 0), 0) -> 0 | I14: =IFERROR(VLOOKUP(LEFT(I$1, LEN(I$1)-1)&TRIM('Allotments (obsolete)'!H14), numPeriods!$A$2:$B$85, 2, 0), 0) -> 0 | J14: =IFERROR(VLOOKUP(LEFT(J$1, LEN(J$1)-1)&TRIM('Allotments (obsolete)'!I14), numPeriods!$A$2:$B$85, 2, 0), 0) -> 0 | K14: =IFERROR(VLOOKUP(LEFT(K$1, LEN(K$1)-1)&TRIM('Allotments (obsolete)'!J14), numPeriods!$A$2:$B$85, 2, 0), 0) -> 7 | ... O14: =IFERROR(VLOOKUP(LEFT(O$1, LEN(O$1)-1)&TRIM('Allotments (obsolete)'!N14), numPeriods!$A$2:$B$85, 2, 0), 0) -> 0 | P14: =SUM(D14:O14) -> 28 | V14: =P14+U14 -> 28
A15: 13 | B15: SH | C15: 8A | D15: =IFERROR(VLOOKUP(LEFT(D$1, LEN(D$1)-1)&TRIM('Allotments (obsolete)'!C15), numPeriods!$A$2:$B$85, 2, 0), 0) -> 0 | E15: =IFERROR(VLOOKUP(LEFT(E$1, LEN(E$1)-1)&TRIM('Allotments (obsolete)'!D15), numPeriods!$A$2:$B$85, 2, 0), 0) -> 0 | F15: =IFERROR(VLOOKUP(LEFT(F$1, LEN(F$1)-1)&TRIM('Allotments (obsolete)'!E15), numPeriods!$A$2:$B$85, 2, 0), 0) -> 2 | G15: =IFERROR(VLOOKUP(LEFT(G$1, LEN(G$1)-1)&TRIM('Allotments (obsolete)'!F15), numPeriods!$A$2:$B$85, 2, 0), 0) -> 0 | H15: =IFERROR(VLOOKUP(LEFT(H$1, LEN(H$1)-1)&TRIM('Allotments (obsolete)'!G15), numPeriods!$A$2:$B$85, 2, 0), 0) -> 8 | I15: =IFERROR(VLOOKUP(LEFT(I$1, LEN(I$1)-1)&TRIM('Allotments (obsolete)'!H15), numPeriods!$A$2:$B$85, 2, 0), 0) -> 0 | J15: =IFERROR(VLOOKUP(LEFT(J$1, LEN(J$1)-1)&TRIM('Allotments (obsolete)'!I15), numPeriods!$A$2:$B$85, 2, 0), 0) -> 0 | K15: =IFERROR(VLOOKUP(LEFT(K$1, LEN(K$1)-1)&TRIM('Allotments (obsolete)'!J15), numPeriods!$A$2:$B$85, 2, 0), 0) -> 6 | ... O15: =IFERROR(VLOOKUP(LEFT(O$1, LEN(O$1)-1)&TRIM('Allotments (obsolete)'!N15), numPeriods!$A$2:$B$85, 2, 0), 0) -> 7 | P15: =SUM(D15:O15) -> 30 | V15: =P15+U15 -> 30
A16: 14 | B16: RN | C16: 7B | D16: =IFERROR(VLOOKUP(LEFT(D$1, LEN(D$1)-1)&TRIM('Allotments (obsolete)'!C16), numPeriods!$A$2:$B$85, 2, 0), 0) -> 0 | E16: =IFERROR(VLOOKUP(LEFT(E$1, LEN(E$1)-1)&TRIM('Allotments (obsolete)'!D16), numPeriods!$A$2:$B$85, 2, 0), 0) -> 10 | F16: =IFERROR(VLOOKUP(LEFT(F$1, LEN(F$1)-1)&TRIM('Allotments (obsolete)'!E16), numPeriods!$A$2:$B$85, 2, 0), 0) -> 8 | G16: =IFERROR(VLOOKUP(LEFT(G$1, LEN(G$1)-1)&TRIM('Allotments (obsolete)'!F16), numPeriods!$A$2:$B$85, 2, 0), 0) -> 0 | H16: =IFERROR(VLOOKUP(LEFT(H$1, LEN(H$1)-1)&TRIM('Allotments (obsolete)'!G16), numPeriods!$A$2:$B$85, 2, 0), 0) -> 0 | I16: =IFERROR(VLOOKUP(LEFT(I$1, LEN(I$1)-1)&TRIM('Allotments (obsolete)'!H16), numPeriods!$A$2:$B$85, 2, 0), 0) -> 8 | J16: =IFERROR(VLOOKUP(LEFT(J$1, LEN(J$1)-1)&TRIM('Allotments (obsolete)'!I16), numPeriods!$A$2:$B$85, 2, 0), 0) -> 0 | K16: =IFERROR(VLOOKUP(LEFT(K$1, LEN(K$1)-1)&TRIM('Allotments (obsolete)'!J16), numPeriods!$A$2:$B$85, 2, 0), 0) -> 0 | ... O16: =IFERROR(VLOOKUP(LEFT(O$1, LEN(O$1)-1)&TRIM('Allotments (obsolete)'!N16), numPeriods!$A$2:$B$85, 2, 0), 0) -> 0 | P16: =SUM(D16:O16) -> 26 | V16: =P16+U16 -> 26
A17: 15 | B17: RS | D17: =IFERROR(VLOOKUP(LEFT(D$1, LEN(D$1)-1)&TRIM('Allotments (obsolete)'!C17), numPeriods!$A$2:$B$85, 2, 0), 0) -> 8 | E17: =IFERROR(VLOOKUP(LEFT(E$1, LEN(E$1)-1)&TRIM('Allotments (obsolete)'!D17), numPeriods!$A$2:$B$85, 2, 0), 0) -> 0 | F17: =IFERROR(VLOOKUP(LEFT(F$1, LEN(F$1)-1)&TRIM('Allotments (obsolete)'!E17), numPeriods!$A$2:$B$85, 2, 0), 0) -> 0 | G17: =IFERROR(VLOOKUP(LEFT(G$1, LEN(G$1)-1)&TRIM('Allotments (obsolete)'!F17), numPeriods!$A$2:$B$85, 2, 0), 0) -> 0 | H17: =IFERROR(VLOOKUP(LEFT(H$1, LEN(H$1)-1)&TRIM('Allotments (obsolete)'!G17), numPeriods!$A$2:$B$85, 2, 0), 0) -> 0 | I17: =IFERROR(VLOOKUP(LEFT(I$1, LEN(I$1)-1)&TRIM('Allotments (obsolete)'!H17), numPeriods!$A$2:$B$85, 2, 0), 0) -> 2 | J17: =IFERROR(VLOOKUP(LEFT(J$1, LEN(J$1)-1)&TRIM('Allotments (obsolete)'!I17), numPeriods!$A$2:$B$85, 2, 0), 0) -> 13 | K17: =IFERROR(VLOOKUP(LEFT(K$1, LEN(K$1)-1)&TRIM('Allotments (obsolete)'!J17), numPeriods!$A$2:$B$85, 2, 0), 0) -> 0 | ... O17: =IFERROR(VLOOKUP(LEFT(O$1, LEN(O$1)-1)&TRIM('Allotments (obsolete)'!N17), numPeriods!$A$2:$B$85, 2, 0), 0) -> 0 | P17: =SUM(D17:O17) -> 30 | V17: =P17+U17 -> 30
A18: 16 | B18: AB | C18: 10C | D18: =IFERROR(VLOOKUP(LEFT(D$1, LEN(D$1)-1)&TRIM('Allotments (obsolete)'!C18), numPeriods!$A$2:$B$85, 2, 0), 0) -> 6 | E18: =IFERROR(VLOOKUP(LEFT(E$1, LEN(E$1)-1)&TRIM('Allotments (obsolete)'!D18), numPeriods!$A$2:$B$85, 2, 0), 0) -> 0 | F18: =IFERROR(VLOOKUP(LEFT(F$1, LEN(F$1)-1)&TRIM('Allotments (obsolete)'!E18), numPeriods!$A$2:$B$85, 2, 0), 0) -> 0 | G18: =IFERROR(VLOOKUP(LEFT(G$1, LEN(G$1)-1)&TRIM('Allotments (obsolete)'!F18), numPeriods!$A$2:$B$85, 2, 0), 0) -> 6 | H18: =IFERROR(VLOOKUP(LEFT(H$1, LEN(H$1)-1)&TRIM('Allotments (obsolete)'!G18), numPeriods!$A$2:$B$85, 2, 0), 0) -> 6 | I18: =IFERROR(VLOOKUP(LEFT(I$1, LEN(I$1)-1)&TRIM('Allotments (obsolete)'!H18), numPeriods!$A$2:$B$85, 2, 0), 0) -> 0 | J18: =IFERROR(VLOOKUP(LEFT(J$1, LEN(J$1)-1)&TRIM('Allotments (obsolete)'!I18), numPeriods!$A$2:$B$85, 2, 0), 0) -> 6 | K18: =IFERROR(VLOOKUP(LEFT(K$1, LEN(K$1)-1)&TRIM('Allotments (obsolete)'!J18), numPeriods!$A$2:$B$85, 2, 0), 0) -> 0 | ... O18: =IFERROR(VLOOKUP(LEFT(O$1, LEN(O$1)-1)&TRIM('Allotments (obsolete)'!N18), numPeriods!$A$2:$B$85, 2, 0), 0) -> 6 | P18: =SUM(D18:O18) -> 36 | V18: =P18+U18 -> 36
A19: 17 | B19: GK | D19: =IFERROR(VLOOKUP(LEFT(D$1, LEN(D$1)-1)&TRIM('Allotments (obsolete)'!C19), numPeriods!$A$2:$B$85, 2, 0), 0) -> 0 | E19: =IFERROR(VLOOKUP(LEFT(E$1, LEN(E$1)-1)&TRIM('Allotments (obsolete)'!D19), numPeriods!$A$2:$B$85, 2, 0), 0) -> 6 | F19: =IFERROR(VLOOKUP(LEFT(F$1, LEN(F$1)-1)&TRIM('Allotments (obsolete)'!E19), numPeriods!$A$2:$B$85, 2, 0), 0) -> 6 | G19: =IFERROR(VLOOKUP(LEFT(G$1, LEN(G$1)-1)&TRIM('Allotments (obsolete)'!F19), numPeriods!$A$2:$B$85, 2, 0), 0) -> 0 | H19: =IFERROR(VLOOKUP(LEFT(H$1, LEN(H$1)-1)&TRIM('Allotments (obsolete)'!G19), numPeriods!$A$2:$B$85, 2, 0), 0) -> 0 | I19: =IFERROR(VLOOKUP(LEFT(I$1, LEN(I$1)-1)&TRIM('Allotments (obsolete)'!H19), numPeriods!$A$2:$B$85, 2, 0), 0) -> 6 | J19: =IFERROR(VLOOKUP(LEFT(J$1, LEN(J$1)-1)&TRIM('Allotments (obsolete)'!I19), numPeriods!$A$2:$B$85, 2, 0), 0) -> 0 | K19: =IFERROR(VLOOKUP(LEFT(K$1, LEN(K$1)-1)&TRIM('Allotments (obsolete)'!J19), numPeriods!$A$2:$B$85, 2, 0), 0) -> 6 | ... O19: =IFERROR(VLOOKUP(LEFT(O$1, LEN(O$1)-1)&TRIM('Allotments (obsolete)'!N19), numPeriods!$A$2:$B$85, 2, 0), 0) -> 0 | P19: =SUM(D19:O19) -> 36 | V19: =P19+U19 -> 36
A20: 18 | B20: VS | D20: =IFERROR(VLOOKUP(LEFT(D$1, LEN(D$1)-1)&TRIM('Allotments (obsolete)'!C20), numPeriods!$A$2:$B$85, 2, 0), 0) -> 0 | E20: =IFERROR(VLOOKUP(LEFT(E$1, LEN(E$1)-1)&TRIM('Allotments (obsolete)'!D20), numPeriods!$A$2:$B$85, 2, 0), 0) -> 0 | F20: =IFERROR(VLOOKUP(LEFT(F$1, LEN(F$1)-1)&TRIM('Allotments (obsolete)'!E20), numPeriods!$A$2:$B$85, 2, 0), 0) -> 0 | G20: =IFERROR(VLOOKUP(LEFT(G$1, LEN(G$1)-1)&TRIM('Allotments (obsolete)'!F20), numPeriods!$A$2:$B$85, 2, 0), 0) -> 0 | H20: =IFERROR(VLOOKUP(LEFT(H$1, LEN(H$1)-1)&TRIM('Allotments (obsolete)'!G20), numPeriods!$A$2:$B$85, 2, 0), 0) -> 9 | I20: =IFERROR(VLOOKUP(LEFT(I$1, LEN(I$1)-1)&TRIM('Allotments (obsolete)'!H20), numPeriods!$A$2:$B$85, 2, 0), 0) -> 0 | J20: =IFERROR(VLOOKUP(LEFT(J$1, LEN(J$1)-1)&TRIM('Allotments (obsolete)'!I20), numPeriods!$A$2:$B$85, 2, 0), 0) -> 0 | K20: =IFERROR(VLOOKUP(LEFT(K$1, LEN(K$1)-1)&TRIM('Allotments (obsolete)'!J20), numPeriods!$A$2:$B$85, 2, 0), 0) -> 10 | ... O20: =IFERROR(VLOOKUP(LEFT(O$1, LEN(O$1)-1)&TRIM('Allotments (obsolete)'!N20), numPeriods!$A$2:$B$85, 2, 0), 0) -> 7 | P20: =SUM(D20:O20) -> 33 | V20: =P20+U20 -> 33
A21: 19 | B21: SU | C21: 10B | D21: =IFERROR(VLOOKUP(LEFT(D$1, LEN(D$1)-1)&TRIM('Allotments (obsolete)'!C21), numPeriods!$A$2:$B$85, 2, 0), 0) -> 0 | E21: =IFERROR(VLOOKUP(LEFT(E$1, LEN(E$1)-1)&TRIM('Allotments (obsolete)'!D21), numPeriods!$A$2:$B$85, 2, 0), 0) -> 6 | F21: =IFERROR(VLOOKUP(LEFT(F$1, LEN(F$1)-1)&TRIM('Allotments (obsolete)'!E21), numPeriods!$A$2:$B$85, 2, 0), 0) -> 0 | G21: =IFERROR(VLOOKUP(LEFT(G$1, LEN(G$1)-1)&TRIM('Allotments (obsolete)'!F21), numPeriods!$A$2:$B$85, 2, 0), 0) -> 9 | H21: =IFERROR(VLOOKUP(LEFT(H$1, LEN(H$1)-1)&TRIM('Allotments (obsolete)'!G21), numPeriods!$A$2:$B$85, 2, 0), 0) -> 0 | I21: =IFERROR(VLOOKUP(LEFT(I$1, LEN(I$1)-1)&TRIM('Allotments (obsolete)'!H21), numPeriods!$A$2:$B$85, 2, 0), 0) -> 0 | J21: =IFERROR(VLOOKUP(LEFT(J$1, LEN(J$1)-1)&TRIM('Allotments (obsolete)'!I21), numPeriods!$A$2:$B$85, 2, 0), 0) -> 10 | K21: =IFERROR(VLOOKUP(LEFT(K$1, LEN(K$1)-1)&TRIM('Allotments (obsolete)'!J21), numPeriods!$A$2:$B$85, 2, 0), 0) -> 0 | ... O21: =IFERROR(VLOOKUP(LEFT(O$1, LEN(O$1)-1)&TRIM('Allotments (obsolete)'!N21), numPeriods!$A$2:$B$85, 2, 0), 0) -> 0 | P21: =SUM(D21:O21) -> 32 | V21: =P21+U21 -> 32
A22: 20 | B22: RI | C22: 8B | D22: =IFERROR(VLOOKUP(LEFT(D$1, LEN(D$1)-1)&TRIM('Allotments (obsolete)'!C22), numPeriods!$A$2:$B$85, 2, 0), 0) -> 6 | E22: =IFERROR(VLOOKUP(LEFT(E$1, LEN(E$1)-1)&TRIM('Allotments (obsolete)'!D22), numPeriods!$A$2:$B$85, 2, 0), 0) -> 0 | F22: =IFERROR(VLOOKUP(LEFT(F$1, LEN(F$1)-1)&TRIM('Allotments (obsolete)'!E22), numPeriods!$A$2:$B$85, 2, 0), 0) -> 9 | G22: =IFERROR(VLOOKUP(LEFT(G$1, LEN(G$1)-1)&TRIM('Allotments (obsolete)'!F22), numPeriods!$A$2:$B$85, 2, 0), 0) -> 0 | H22: =IFERROR(VLOOKUP(LEFT(H$1, LEN(H$1)-1)&TRIM('Allotments (obsolete)'!G22), numPeriods!$A$2:$B$85, 2, 0), 0) -> 0 | I22: =IFERROR(VLOOKUP(LEFT(I$1, LEN(I$1)-1)&TRIM('Allotments (obsolete)'!H22), numPeriods!$A$2:$B$85, 2, 0), 0) -> 9 | J22: =IFERROR(VLOOKUP(LEFT(J$1, LEN(J$1)-1)&TRIM('Allotments (obsolete)'!I22), numPeriods!$A$2:$B$85, 2, 0), 0) -> 0 | K22: =IFERROR(VLOOKUP(LEFT(K$1, LEN(K$1)-1)&TRIM('Allotments (obsolete)'!J22), numPeriods!$A$2:$B$85, 2, 0), 0) -> 0 | ... O22: =IFERROR(VLOOKUP(LEFT(O$1, LEN(O$1)-1)&TRIM('Allotments (obsolete)'!N22), numPeriods!$A$2:$B$85, 2, 0), 0) -> 0 | P22: =SUM(D22:O22) -> 31 | V22: =P22+U22 -> 31
A23: 21 | B23: JL | C23: 8A | D23: =IFERROR(VLOOKUP(LEFT(D$1, LEN(D$1)-1)&TRIM('Allotments (obsolete)'!C23), numPeriods!$A$2:$B$85, 2, 0), 0) -> 6 | E23: =IFERROR(VLOOKUP(LEFT(E$1, LEN(E$1)-1)&TRIM('Allotments (obsolete)'!D23), numPeriods!$A$2:$B$85, 2, 0), 0) -> 0 | F23: =IFERROR(VLOOKUP(LEFT(F$1, LEN(F$1)-1)&TRIM('Allotments (obsolete)'!E23), numPeriods!$A$2:$B$85, 2, 0), 0) -> 0 | G23: =IFERROR(VLOOKUP(LEFT(G$1, LEN(G$1)-1)&TRIM('Allotments (obsolete)'!F23), numPeriods!$A$2:$B$85, 2, 0), 0) -> 0 | H23: =IFERROR(VLOOKUP(LEFT(H$1, LEN(H$1)-1)&TRIM('Allotments (obsolete)'!G23), numPeriods!$A$2:$B$85, 2, 0), 0) -> 0 | I23: =IFERROR(VLOOKUP(LEFT(I$1, LEN(I$1)-1)&TRIM('Allotments (obsolete)'!H23), numPeriods!$A$2:$B$85, 2, 0), 0) -> 6 | J23: =IFERROR(VLOOKUP(LEFT(J$1, LEN(J$1)-1)&TRIM('Allotments (obsolete)'!I23), numPeriods!$A$2:$B$85, 2, 0), 0) -> 5 | K23: =IFERROR(VLOOKUP(LEFT(K$1, LEN(K$1)-1)&TRIM('Allotments (obsolete)'!J23), numPeriods!$A$2:$B$85, 2, 0), 0) -> 0 | ... O23: =IFERROR(VLOOKUP(LEFT(O$1, LEN(O$1)-1)&TRIM('Allotments (obsolete)'!N23), numPeriods!$A$2:$B$85, 2, 0), 0) -> 7 | P23: =SUM(D23:O23) -> 29 | V23: =P23+U23 -> 29
A24: 22 | B24: MB | C24: 9A | D24: =IFERROR(VLOOKUP(LEFT(D$1, LEN(D$1)-1)&TRIM('Allotments (obsolete)'!C24), numPeriods!$A$2:$B$85, 2, 0), 0) -> 0 | E24: =IFERROR(VLOOKUP(LEFT(E$1, LEN(E$1)-1)&TRIM('Allotments (obsolete)'!D24), numPeriods!$A$2:$B$85, 2, 0), 0) -> 8 | F24: =IFERROR(VLOOKUP(LEFT(F$1, LEN(F$1)-1)&TRIM('Allotments (obsolete)'!E24), numPeriods!$A$2:$B$85, 2, 0), 0) -> 0 | G24: =IFERROR(VLOOKUP(LEFT(G$1, LEN(G$1)-1)&TRIM('Allotments (obsolete)'!F24), numPeriods!$A$2:$B$85, 2, 0), 0) -> 0 | H24: =IFERROR(VLOOKUP(LEFT(H$1, LEN(H$1)-1)&TRIM('Allotments (obsolete)'!G24), numPeriods!$A$2:$B$85, 2, 0), 0) -> 0 | I24: =IFERROR(VLOOKUP(LEFT(I$1, LEN(I$1)-1)&TRIM('Allotments (obsolete)'!H24), numPeriods!$A$2:$B$85, 2, 0), 0) -> 0 | J24: =IFERROR(VLOOKUP(LEFT(J$1, LEN(J$1)-1)&TRIM('Allotments (obsolete)'!I24), numPeriods!$A$2:$B$85, 2, 0), 0) -> 0 | K24: =IFERROR(VLOOKUP(LEFT(K$1, LEN(K$1)-1)&TRIM('Allotments (obsolete)'!J24), numPeriods!$A$2:$B$85, 2, 0), 0) -> 0 | ... O24: =IFERROR(VLOOKUP(LEFT(O$1, LEN(O$1)-1)&TRIM('Allotments (obsolete)'!N24), numPeriods!$A$2:$B$85, 2, 0), 0) -> 5 | P24: =SUM(D24:O24) -> 32 | V24: =P24+U24 -> 32
A25: 23 | B25: RJ | C25: 6A | D25: =IFERROR(VLOOKUP(LEFT(D$1, LEN(D$1)-1)&TRIM('Allotments (obsolete)'!C25), numPeriods!$A$2:$B$85, 2, 0), 0) -> 0 | E25: =IFERROR(VLOOKUP(LEFT(E$1, LEN(E$1)-1)&TRIM('Allotments (obsolete)'!D25), numPeriods!$A$2:$B$85, 2, 0), 0) -> 0 | F25: =IFERROR(VLOOKUP(LEFT(F$1, LEN(F$1)-1)&TRIM('Allotments (obsolete)'!E25), numPeriods!$A$2:$B$85, 2, 0), 0) -> 8 | G25: =IFERROR(VLOOKUP(LEFT(G$1, LEN(G$1)-1)&TRIM('Allotments (obsolete)'!F25), numPeriods!$A$2:$B$85, 2, 0), 0) -> 8 | H25: =IFERROR(VLOOKUP(LEFT(H$1, LEN(H$1)-1)&TRIM('Allotments (obsolete)'!G25), numPeriods!$A$2:$B$85, 2, 0), 0) -> 6 | I25: =IFERROR(VLOOKUP(LEFT(I$1, LEN(I$1)-1)&TRIM('Allotments (obsolete)'!H25), numPeriods!$A$2:$B$85, 2, 0), 0) -> 0 | J25: =IFERROR(VLOOKUP(LEFT(J$1, LEN(J$1)-1)&TRIM('Allotments (obsolete)'!I25), numPeriods!$A$2:$B$85, 2, 0), 0) -> 0 | K25: =IFERROR(VLOOKUP(LEFT(K$1, LEN(K$1)-1)&TRIM('Allotments (obsolete)'!J25), numPeriods!$A$2:$B$85, 2, 0), 0) -> 7 | ... O25: =IFERROR(VLOOKUP(LEFT(O$1, LEN(O$1)-1)&TRIM('Allotments (obsolete)'!N25), numPeriods!$A$2:$B$85, 2, 0), 0) -> 0 | P25: =SUM(D25:O25) -> 34 | V25: =P25+U25 -> 34
A26: 24 | B26: SN | C26: 11A | D26: =IFERROR(VLOOKUP(LEFT(D$1, LEN(D$1)-1)&TRIM('Allotments (obsolete)'!C26), numPeriods!$A$2:$B$85, 2, 0), 0) -> 0 | E26: =IFERROR(VLOOKUP(LEFT(E$1, LEN(E$1)-1)&TRIM('Allotments (obsolete)'!D26), numPeriods!$A$2:$B$85, 2, 0), 0) -> 0 | F26: =IFERROR(VLOOKUP(LEFT(F$1, LEN(F$1)-1)&TRIM('Allotments (obsolete)'!E26), numPeriods!$A$2:$B$85, 2, 0), 0) -> 0 | G26: =IFERROR(VLOOKUP(LEFT(G$1, LEN(G$1)-1)&TRIM('Allotments (obsolete)'!F26), numPeriods!$A$2:$B$85, 2, 0), 0) -> 0 | H26: =IFERROR(VLOOKUP(LEFT(H$1, LEN(H$1)-1)&TRIM('Allotments (obsolete)'!G26), numPeriods!$A$2:$B$85, 2, 0), 0) -> 8 | I26: =IFERROR(VLOOKUP(LEFT(I$1, LEN(I$1)-1)&TRIM('Allotments (obsolete)'!H26), numPeriods!$A$2:$B$85, 2, 0), 0) -> 8 | J26: =IFERROR(VLOOKUP(LEFT(J$1, LEN(J$1)-1)&TRIM('Allotments (obsolete)'!I26), numPeriods!$A$2:$B$85, 2, 0), 0) -> 0 | K26: =IFERROR(VLOOKUP(LEFT(K$1, LEN(K$1)-1)&TRIM('Allotments (obsolete)'!J26), numPeriods!$A$2:$B$85, 2, 0), 0) -> 5 | ... O26: =IFERROR(VLOOKUP(LEFT(O$1, LEN(O$1)-1)&TRIM('Allotments (obsolete)'!N26), numPeriods!$A$2:$B$85, 2, 0), 0) -> 0 | P26: =SUM(D26:O26) -> 21 | S26: HIS | T26: HIS | U26: 18 | V26: =P26+U26 -> 39
A27: 25 | B27: PR | D27: =IFERROR(VLOOKUP(LEFT(D$1, LEN(D$1)-1)&TRIM('Allotments (obsolete)'!C27), numPeriods!$A$2:$B$85, 2, 0), 0) -> 8 | E27: =IFERROR(VLOOKUP(LEFT(E$1, LEN(E$1)-1)&TRIM('Allotments (obsolete)'!D27), numPeriods!$A$2:$B$85, 2, 0), 0) -> 6 | F27: =IFERROR(VLOOKUP(LEFT(F$1, LEN(F$1)-1)&TRIM('Allotments (obsolete)'!E27), numPeriods!$A$2:$B$85, 2, 0), 0) -> 0 | G27: =IFERROR(VLOOKUP(LEFT(G$1, LEN(G$1)-1)&TRIM('Allotments (obsolete)'!F27), numPeriods!$A$2:$B$85, 2, 0), 0) -> 6 | H27: =IFERROR(VLOOKUP(LEFT(H$1, LEN(H$1)-1)&TRIM('Allotments (obsolete)'!G27), numPeriods!$A$2:$B$85, 2, 0), 0) -> 0 | I27: =IFERROR(VLOOKUP(LEFT(I$1, LEN(I$1)-1)&TRIM('Allotments (obsolete)'!H27), numPeriods!$A$2:$B$85, 2, 0), 0) -> 0 | J27: =IFERROR(VLOOKUP(LEFT(J$1, LEN(J$1)-1)&TRIM('Allotments (obsolete)'!I27), numPeriods!$A$2:$B$85, 2, 0), 0) -> 7 | K27: =IFERROR(VLOOKUP(LEFT(K$1, LEN(K$1)-1)&TRIM('Allotments (obsolete)'!J27), numPeriods!$A$2:$B$85, 2, 0), 0) -> 0 | ... O27: =IFERROR(VLOOKUP(LEFT(O$1, LEN(O$1)-1)&TRIM('Allotments (obsolete)'!N27), numPeriods!$A$2:$B$85, 2, 0), 0) -> 0 | P27: =SUM(D27:O27) -> 34 | V27: =P27+U27 -> 34
A28: 26 | B28: MA | D28: =IFERROR(VLOOKUP(LEFT(D$1, LEN(D$1)-1)&TRIM('Allotments (obsolete)'!C28), numPeriods!$A$2:$B$85, 2, 0), 0) -> 0 | E28: =IFERROR(VLOOKUP(LEFT(E$1, LEN(E$1)-1)&TRIM('Allotments (obsolete)'!D28), numPeriods!$A$2:$B$85, 2, 0), 0) -> 4 | F28: =IFERROR(VLOOKUP(LEFT(F$1, LEN(F$1)-1)&TRIM('Allotments (obsolete)'!E28), numPeriods!$A$2:$B$85, 2, 0), 0) -> 6 | G28: =IFERROR(VLOOKUP(LEFT(G$1, LEN(G$1)-1)&TRIM('Allotments (obsolete)'!F28), numPeriods!$A$2:$B$85, 2, 0), 0) -> 0 | H28: =IFERROR(VLOOKUP(LEFT(H$1, LEN(H$1)-1)&TRIM('Allotments (obsolete)'!G28), numPeriods!$A$2:$B$85, 2, 0), 0) -> 4 | I28: =IFERROR(VLOOKUP(LEFT(I$1, LEN(I$1)-1)&TRIM('Allotments (obsolete)'!H28), numPeriods!$A$2:$B$85, 2, 0), 0) -> 0 | J28: =IFERROR(VLOOKUP(LEFT(J$1, LEN(J$1)-1)&TRIM('Allotments (obsolete)'!I28), numPeriods!$A$2:$B$85, 2, 0), 0) -> 0 | K28: =IFERROR(VLOOKUP(LEFT(K$1, LEN(K$1)-1)&TRIM('Allotments (obsolete)'!J28), numPeriods!$A$2:$B$85, 2, 0), 0) -> 5 | ... O28: =IFERROR(VLOOKUP(LEFT(O$1, LEN(O$1)-1)&TRIM('Allotments (obsolete)'!N28), numPeriods!$A$2:$B$85, 2, 0), 0) -> 5 | P28: =SUM(D28:O28) -> 29 | V28: =P28+U28 -> 29
A29: 27 | B29: RL | D29: =IFERROR(VLOOKUP(LEFT(D$1, LEN(D$1)-1)&TRIM('Allotments (obsolete)'!C29), numPeriods!$A$2:$B$85, 2, 0), 0) -> 4 | E29: =IFERROR(VLOOKUP(LEFT(E$1, LEN(E$1)-1)&TRIM('Allotments (obsolete)'!D29), numPeriods!$A$2:$B$85, 2, 0), 0) -> 0 | F29: =IFERROR(VLOOKUP(LEFT(F$1, LEN(F$1)-1)&TRIM('Allotments (obsolete)'!E29), numPeriods!$A$2:$B$85, 2, 0), 0) -> 4 | G29: =IFERROR(VLOOKUP(LEFT(G$1, LEN(G$1)-1)&TRIM('Allotments (obsolete)'!F29), numPeriods!$A$2:$B$85, 2, 0), 0) -> 4 | H29: =IFERROR(VLOOKUP(LEFT(H$1, LEN(H$1)-1)&TRIM('Allotments (obsolete)'!G29), numPeriods!$A$2:$B$85, 2, 0), 0) -> 0 | I29: =IFERROR(VLOOKUP(LEFT(I$1, LEN(I$1)-1)&TRIM('Allotments (obsolete)'!H29), numPeriods!$A$2:$B$85, 2, 0), 0) -> 4 | J29: =IFERROR(VLOOKUP(LEFT(J$1, LEN(J$1)-1)&TRIM('Allotments (obsolete)'!I29), numPeriods!$A$2:$B$85, 2, 0), 0) -> 5 | K29: =IFERROR(VLOOKUP(LEFT(K$1, LEN(K$1)-1)&TRIM('Allotments (obsolete)'!J29), numPeriods!$A$2:$B$85, 2, 0), 0) -> 0 | ... O29: =IFERROR(VLOOKUP(LEFT(O$1, LEN(O$1)-1)&TRIM('Allotments (obsolete)'!N29), numPeriods!$A$2:$B$85, 2, 0), 0) -> 0 | P29: =SUM(D29:O29) -> 31 | V29: =P29+U29 -> 31
A30: 28 | B30: SR | D30: =IFERROR(VLOOKUP(LEFT(D$1, LEN(D$1)-1)&TRIM('Allotments (obsolete)'!C30), numPeriods!$A$2:$B$85, 2, 0), 0) -> 0 | E30: =IFERROR(VLOOKUP(LEFT(E$1, LEN(E$1)-1)&TRIM('Allotments (obsolete)'!D30), numPeriods!$A$2:$B$85, 2, 0), 0) -> 0 | F30: =IFERROR(VLOOKUP(LEFT(F$1, LEN(F$1)-1)&TRIM('Allotments (obsolete)'!E30), numPeriods!$A$2:$B$85, 2, 0), 0) -> 0 | G30: =IFERROR(VLOOKUP(LEFT(G$1, LEN(G$1)-1)&TRIM('Allotments (obsolete)'!F30), numPeriods!$A$2:$B$85, 2, 0), 0) -> 0 | H30: =IFERROR(VLOOKUP(LEFT(H$1, LEN(H$1)-1)&TRIM('Allotments (obsolete)'!G30), numPeriods!$A$2:$B$85, 2, 0), 0) -> 0 | I30: =IFERROR(VLOOKUP(LEFT(I$1, LEN(I$1)-1)&TRIM('Allotments (obsolete)'!H30), numPeriods!$A$2:$B$85, 2, 0), 0) -> 0 | J30: =IFERROR(VLOOKUP(LEFT(J$1, LEN(J$1)-1)&TRIM('Allotments (obsolete)'!I30), numPeriods!$A$2:$B$85, 2, 0), 0) -> 0 | K30: =IFERROR(VLOOKUP(LEFT(K$1, LEN(K$1)-1)&TRIM('Allotments (obsolete)'!J30), numPeriods!$A$2:$B$85, 2, 0), 0) -> 0 | ... O30: =IFERROR(VLOOKUP(LEFT(O$1, LEN(O$1)-1)&TRIM('Allotments (obsolete)'!N30), numPeriods!$A$2:$B$85, 2, 0), 0) -> 0 | P30: =SUM(D30:O30) -> 0 | V30: =P30+U30 -> 0
V31: =P31+U31 -> 0

Sheet numPeriods
A1: Class-Subject | B1: Periods | C1: Class No | D1: Subject
A2: =C2&D2 -> 6AG | B2: 3 | C2: 6 | D2: AG
A3: =C3&D3 -> 6CS | B3: 4 | C3: 6 | D3: CS
A4: =C4&D4 -> 6EN | B4: 8 | C4: 6 | D4: EN
A5: =C5&D5 -> 6HI | B5: 4 | C5: 6 | D5: HI
A6: =C6&D6 -> 6MATH | B6: 8 | C6: 6 | D6: MATH
A7: =C7&D7 -> 6PBI | B7: 6 | C7: 6 | D7: PBI
A8: =C8&D8 -> 6PE | B8: 2 | C8: 6 | D8: PE
A9: =C9&D9 -> 6SCI | B9: 6 | C9: 6 | D9: SCI
A10: =C10&D10 -> 6SS | B10: 6 | C10: 6 | D10: SS
A11: =C11&D11 -> 6WL | B11: 1 | C11: 6 | D11: WL
A12: 6MATH, PE | B12: 10 | C12: 6
A13: 6SCI, AG | B13: 9 | C13: 6
A14: =C14&D14 -> 7AG | B14: 3 | C14: 7 | D14: AG
A15: =C15&D15 -> 7CS | B15: 4 | C15: 7 | D15: CS
A16: =C16&D16 -> 7EN | B16: 8 | C16: 7 | D16: EN
A17: =C17&D17 -> 7HI | B17: 4 | C17: 7 | D17: HI
A18: =C18&D18 -> 7MATH | B18: 8 | C18: 7 | D18: MATH
A19: =C19&D19 -> 7PBI | B19: 6 | C19: 7 | D19: PBI
A20: =C20&D20 -> 7PE | B20: 2 | C20: 7 | D20: PE
A21: =C21&D21 -> 7SCI | B21: 6 | C21: 7 | D21: SCI
A22: =C22&D22 -> 7SS | B22: 6 | C22: 7 | D22: SS
A23: =C23&D23 -> 7WL | B23: 1 | C23: 7 | D23: WL
A24: 7MATH, PE | B24: 10 | C24: 7
A25: 7SCI, AG | B25: 9 | C25: 7
A26: =C26&D26 -> 8AG | B26: 3 | C26: 8 | D26: AG
A27: =C27&D27 -> 8CS | B27: 4 | C27: 8 | D27: CS
A28: =C28&D28 -> 8EN | B28: 8 | C28: 8 | D28: EN
A29: =C29&D29 -> 8HI | B29: 4 | C29: 8 | D29: HI
A30: =C30&D30 -> 8MATH | B30: 8 | C30: 8 | D30: MATH
A31: =C31&D31 -> 8PBI | B31: 6 | C31: 8 | D31: PBI
A32: =C32&D32 -> 8PE | B32: 2 | C32: 8 | D32: PE
A33: =C33&D33 -> 8SCI | B33: 6 | C33: 8 | D33: SCI
A34: =C34&D34 -> 8SS | B34: 6 | C34: 8 | D34: SS
A35: =C35&D35 -> 8WL | B35: 1 | C35: 8 | D35: WL
A36: 8MATH, PE | B36: 10 | C36: 8
A37: 8SCI, AG | B37: 9 | C37: 8
A38: =C38&D38 -> 9CS | B38: 4 | C38: 9 | D38: CS
A39: =C39&D39 -> 9EN | B39: 7 | C39: 9 | D39: EN
A40: =C40&D40 -> 9HI | B40: 5 | C40: 9 | D40: HI
...

Sheet info sheet
A1: This workbook is about class allotment to teachers in the year 2025-26.
